{
 "cells": [
  {
   "cell_type": "code",
   "execution_count": 1,
   "id": "95706a33-f665-4087-adb3-cf514aae96b9",
   "metadata": {
    "tags": []
   },
   "outputs": [],
   "source": [
    "import numpy as np\n",
    "import pandas as pd\n",
    "import matplotlib.pyplot as plt\n",
    "\n",
    "from sklearn.preprocessing import LabelEncoder\n",
    "from sklearn.model_selection import train_test_split\n",
    "\n",
    "import cv2\n",
    "import tensorflow as tf\n",
    "from tensorflow import keras\n",
    "from keras import layers\n",
    "from functools import partial\n",
    "\n",
    "import os\n",
    "import xml.etree.ElementTree as ET\n",
    "\n",
    "import warnings\n",
    "warnings.filterwarnings('ignore')\n",
    "AUTO = tf.data.experimental.AUTOTUNE\n"
   ]
  },
  {
   "cell_type": "code",
   "execution_count": 2,
   "id": "6ee3c706-d9e0-449b-a860-a07d1e24a9aa",
   "metadata": {
    "tags": []
   },
   "outputs": [],
   "source": [
    "# # Extract zip file downloaded from kaggle\n",
    "# from zipfile import ZipFile\n",
    "# data_path = r'C:\\Users\\haris\\AI\\ML\\Projects\\Dog Breed Classification\\archive.zip'\n",
    "\n",
    "# with ZipFile(data_path, 'r') as zip:\n",
    "# \tzip.extractall()\n",
    "# \tprint('The data set has been extracted.')"
   ]
  },
  {
   "cell_type": "code",
   "execution_count": 3,
   "id": "b1b185fa-ad76-4430-8380-da29c8fd4fdc",
   "metadata": {
    "tags": []
   },
   "outputs": [],
   "source": [
    "# Path to the folders containing images and annotations\n",
    "annotations_folder = r'C:\\Users\\haris\\AI\\ML\\Projects\\Dog Breed Classification\\annotations'\n",
    "images_folder = r'C:\\Users\\haris\\AI\\ML\\Projects\\Dog Breed Classification\\images'\n",
    "\n",
    "# Initialize lists to store image data and labels\n",
    "images = []\n",
    "labels = []\n",
    "\n",
    "# Parse XML annotations and load images\n",
    "for breed_folder in os.listdir(annotations_folder):\n",
    "    breed_path = os.path.join(annotations_folder, breed_folder)\n",
    "    for annotation_file in os.listdir(breed_path):\n",
    "        annotation_path = os.path.join(breed_path, annotation_file)\n",
    "        \n",
    "        tree = ET.parse(annotation_path)\n",
    "        root = tree.getroot()\n",
    "        \n",
    "        breed = root.find('object/name').text\n",
    "        xmin = int(root.find('object/bndbox/xmin').text)\n",
    "        ymin = int(root.find('object/bndbox/ymin').text)\n",
    "        xmax = int(root.find('object/bndbox/xmax').text)\n",
    "        ymax = int(root.find('object/bndbox/ymax').text)\n",
    "        \n",
    "        img_path = os.path.join(images_folder, breed_folder, annotation_file + '.jpg')\n",
    "        image = cv2.imread(img_path)\n",
    "        image = cv2.resize(image, (224, 224))  # Resize to desired size\n",
    "        \n",
    "        images.append(image)\n",
    "        labels.append(breed)\n",
    "\n",
    "# Convert labels to numerical format\n",
    "label_encoder = LabelEncoder()\n",
    "labels_encoded = label_encoder.fit_transform(labels)"
   ]
  },
  {
   "cell_type": "code",
   "execution_count": 4,
   "id": "8b3128a7-ba2a-467d-bb17-f1ffc8f95c36",
   "metadata": {
    "tags": []
   },
   "outputs": [
    {
     "name": "stdout",
     "output_type": "stream",
     "text": [
      "Train data shape: (14406, 224, 224, 3)\n",
      "Validation data shape: (3087, 224, 224, 3)\n",
      "Test data shape: (3087, 224, 224, 3)\n",
      "Train labels shape: (14406,)\n",
      "Validation labels shape: (3087,)\n",
      "Test labels shape: (3087,)\n"
     ]
    }
   ],
   "source": [
    "# Split data into training, validation, and testing sets\n",
    "X_train, X_temp, y_train, y_temp = train_test_split(images, labels_encoded, test_size=0.3, random_state=42)\n",
    "X_val, X_test, y_val, y_test = train_test_split(X_temp, y_temp, test_size=0.5, random_state=42)\n",
    "\n",
    "# Convert lists to numpy arrays\n",
    "X_train = np.array(X_train)\n",
    "X_val = np.array(X_val)\n",
    "X_test = np.array(X_test)\n",
    "y_train = np.array(y_train)\n",
    "y_val = np.array(y_val)\n",
    "y_test = np.array(y_test)\n",
    "\n",
    "# Print dataset shapes for verification\n",
    "print(\"Train data shape:\", X_train.shape)\n",
    "print(\"Validation data shape:\", X_val.shape)\n",
    "print(\"Test data shape:\", X_test.shape)\n",
    "print(\"Train labels shape:\", y_train.shape)\n",
    "print(\"Validation labels shape:\", y_val.shape)\n",
    "print(\"Test labels shape:\", y_test.shape)\n"
   ]
  },
  {
   "cell_type": "code",
   "execution_count": 5,
   "id": "72cfb460-5117-4b87-8a40-d5dad6a974a7",
   "metadata": {
    "tags": []
   },
   "outputs": [
    {
     "name": "stdout",
     "output_type": "stream",
     "text": [
      "Downloading data from https://storage.googleapis.com/tensorflow/keras-applications/xception/xception_weights_tf_dim_ordering_tf_kernels_notop.h5\n",
      "83683744/83683744 [==============================] - 24s 0us/step\n",
      "Epoch 1/10\n",
      "451/451 [==============================] - 65s 89ms/step - loss: 5.0801 - accuracy: 0.0117 - val_loss: 4.8085 - val_accuracy: 0.0078\n",
      "Epoch 2/10\n",
      "451/451 [==============================] - 38s 84ms/step - loss: 4.7802 - accuracy: 0.0146 - val_loss: 4.7928 - val_accuracy: 0.0091\n",
      "Epoch 3/10\n",
      "451/451 [==============================] - 38s 84ms/step - loss: 4.7618 - accuracy: 0.0161 - val_loss: 4.7863 - val_accuracy: 0.0100\n",
      "Epoch 4/10\n",
      "451/451 [==============================] - 38s 85ms/step - loss: 4.7424 - accuracy: 0.0185 - val_loss: 4.7888 - val_accuracy: 0.0097\n",
      "Epoch 5/10\n",
      "451/451 [==============================] - 38s 85ms/step - loss: 4.7171 - accuracy: 0.0204 - val_loss: 4.7979 - val_accuracy: 0.0136\n",
      "Epoch 6/10\n",
      "451/451 [==============================] - 39s 86ms/step - loss: 4.6936 - accuracy: 0.0217 - val_loss: 4.7621 - val_accuracy: 0.0136\n",
      "Epoch 7/10\n",
      "451/451 [==============================] - 39s 86ms/step - loss: 4.6384 - accuracy: 0.0269 - val_loss: 4.7412 - val_accuracy: 0.0243\n",
      "Epoch 8/10\n",
      "451/451 [==============================] - 39s 86ms/step - loss: 4.5408 - accuracy: 0.0342 - val_loss: 4.7221 - val_accuracy: 0.0185\n",
      "Epoch 9/10\n",
      "451/451 [==============================] - 39s 86ms/step - loss: 4.4710 - accuracy: 0.0393 - val_loss: 4.6566 - val_accuracy: 0.0217\n",
      "Epoch 10/10\n",
      "451/451 [==============================] - 40s 88ms/step - loss: 4.4239 - accuracy: 0.0443 - val_loss: 4.6865 - val_accuracy: 0.0198\n"
     ]
    },
    {
     "ename": "ResourceExhaustedError",
     "evalue": "Graph execution error:\n\nDetected at node 'model/block2_sepconv1/separable_conv2d' defined at (most recent call last):\n    File \"C:\\Users\\haris\\anaconda3\\envs\\tensorflow-gpu\\lib\\runpy.py\", line 196, in _run_module_as_main\n      return _run_code(code, main_globals, None,\n    File \"C:\\Users\\haris\\anaconda3\\envs\\tensorflow-gpu\\lib\\runpy.py\", line 86, in _run_code\n      exec(code, run_globals)\n    File \"C:\\Users\\haris\\anaconda3\\envs\\tensorflow-gpu\\lib\\site-packages\\ipykernel_launcher.py\", line 17, in <module>\n      app.launch_new_instance()\n    File \"C:\\Users\\haris\\anaconda3\\envs\\tensorflow-gpu\\lib\\site-packages\\traitlets\\config\\application.py\", line 1043, in launch_instance\n      app.start()\n    File \"C:\\Users\\haris\\anaconda3\\envs\\tensorflow-gpu\\lib\\site-packages\\ipykernel\\kernelapp.py\", line 712, in start\n      self.io_loop.start()\n    File \"C:\\Users\\haris\\anaconda3\\envs\\tensorflow-gpu\\lib\\site-packages\\tornado\\platform\\asyncio.py\", line 215, in start\n      self.asyncio_loop.run_forever()\n    File \"C:\\Users\\haris\\anaconda3\\envs\\tensorflow-gpu\\lib\\asyncio\\base_events.py\", line 603, in run_forever\n      self._run_once()\n    File \"C:\\Users\\haris\\anaconda3\\envs\\tensorflow-gpu\\lib\\asyncio\\base_events.py\", line 1909, in _run_once\n      handle._run()\n    File \"C:\\Users\\haris\\anaconda3\\envs\\tensorflow-gpu\\lib\\asyncio\\events.py\", line 80, in _run\n      self._context.run(self._callback, *self._args)\n    File \"C:\\Users\\haris\\anaconda3\\envs\\tensorflow-gpu\\lib\\site-packages\\ipykernel\\kernelbase.py\", line 510, in dispatch_queue\n      await self.process_one()\n    File \"C:\\Users\\haris\\anaconda3\\envs\\tensorflow-gpu\\lib\\site-packages\\ipykernel\\kernelbase.py\", line 499, in process_one\n      await dispatch(*args)\n    File \"C:\\Users\\haris\\anaconda3\\envs\\tensorflow-gpu\\lib\\site-packages\\ipykernel\\kernelbase.py\", line 406, in dispatch_shell\n      await result\n    File \"C:\\Users\\haris\\anaconda3\\envs\\tensorflow-gpu\\lib\\site-packages\\ipykernel\\kernelbase.py\", line 730, in execute_request\n      reply_content = await reply_content\n    File \"C:\\Users\\haris\\anaconda3\\envs\\tensorflow-gpu\\lib\\site-packages\\ipykernel\\ipkernel.py\", line 383, in do_execute\n      res = shell.run_cell(\n    File \"C:\\Users\\haris\\anaconda3\\envs\\tensorflow-gpu\\lib\\site-packages\\ipykernel\\zmqshell.py\", line 528, in run_cell\n      return super().run_cell(*args, **kwargs)\n    File \"C:\\Users\\haris\\anaconda3\\envs\\tensorflow-gpu\\lib\\site-packages\\IPython\\core\\interactiveshell.py\", line 3009, in run_cell\n      result = self._run_cell(\n    File \"C:\\Users\\haris\\anaconda3\\envs\\tensorflow-gpu\\lib\\site-packages\\IPython\\core\\interactiveshell.py\", line 3064, in _run_cell\n      result = runner(coro)\n    File \"C:\\Users\\haris\\anaconda3\\envs\\tensorflow-gpu\\lib\\site-packages\\IPython\\core\\async_helpers.py\", line 129, in _pseudo_sync_runner\n      coro.send(None)\n    File \"C:\\Users\\haris\\anaconda3\\envs\\tensorflow-gpu\\lib\\site-packages\\IPython\\core\\interactiveshell.py\", line 3269, in run_cell_async\n      has_raised = await self.run_ast_nodes(code_ast.body, cell_name,\n    File \"C:\\Users\\haris\\anaconda3\\envs\\tensorflow-gpu\\lib\\site-packages\\IPython\\core\\interactiveshell.py\", line 3448, in run_ast_nodes\n      if await self.run_code(code, result, async_=asy):\n    File \"C:\\Users\\haris\\anaconda3\\envs\\tensorflow-gpu\\lib\\site-packages\\IPython\\core\\interactiveshell.py\", line 3508, in run_code\n      exec(code_obj, self.user_global_ns, self.user_ns)\n    File \"C:\\Users\\haris\\AppData\\Local\\Temp\\ipykernel_16188\\2356912300.py\", line 26, in <module>\n      history = model.fit(X_train, y_train, epochs=10, validation_data=(X_val, y_val))\n    File \"C:\\Users\\haris\\anaconda3\\envs\\tensorflow-gpu\\lib\\site-packages\\keras\\utils\\traceback_utils.py\", line 65, in error_handler\n      return fn(*args, **kwargs)\n    File \"C:\\Users\\haris\\anaconda3\\envs\\tensorflow-gpu\\lib\\site-packages\\keras\\engine\\training.py\", line 1606, in fit\n      val_logs = self.evaluate(\n    File \"C:\\Users\\haris\\anaconda3\\envs\\tensorflow-gpu\\lib\\site-packages\\keras\\utils\\traceback_utils.py\", line 65, in error_handler\n      return fn(*args, **kwargs)\n    File \"C:\\Users\\haris\\anaconda3\\envs\\tensorflow-gpu\\lib\\site-packages\\keras\\engine\\training.py\", line 1947, in evaluate\n      tmp_logs = self.test_function(iterator)\n    File \"C:\\Users\\haris\\anaconda3\\envs\\tensorflow-gpu\\lib\\site-packages\\keras\\engine\\training.py\", line 1727, in test_function\n      return step_function(self, iterator)\n    File \"C:\\Users\\haris\\anaconda3\\envs\\tensorflow-gpu\\lib\\site-packages\\keras\\engine\\training.py\", line 1713, in step_function\n      outputs = model.distribute_strategy.run(run_step, args=(data,))\n    File \"C:\\Users\\haris\\anaconda3\\envs\\tensorflow-gpu\\lib\\site-packages\\keras\\engine\\training.py\", line 1701, in run_step\n      outputs = model.test_step(data)\n    File \"C:\\Users\\haris\\anaconda3\\envs\\tensorflow-gpu\\lib\\site-packages\\keras\\engine\\training.py\", line 1665, in test_step\n      y_pred = self(x, training=False)\n    File \"C:\\Users\\haris\\anaconda3\\envs\\tensorflow-gpu\\lib\\site-packages\\keras\\utils\\traceback_utils.py\", line 65, in error_handler\n      return fn(*args, **kwargs)\n    File \"C:\\Users\\haris\\anaconda3\\envs\\tensorflow-gpu\\lib\\site-packages\\keras\\engine\\training.py\", line 557, in __call__\n      return super().__call__(*args, **kwargs)\n    File \"C:\\Users\\haris\\anaconda3\\envs\\tensorflow-gpu\\lib\\site-packages\\keras\\utils\\traceback_utils.py\", line 65, in error_handler\n      return fn(*args, **kwargs)\n    File \"C:\\Users\\haris\\anaconda3\\envs\\tensorflow-gpu\\lib\\site-packages\\keras\\engine\\base_layer.py\", line 1097, in __call__\n      outputs = call_fn(inputs, *args, **kwargs)\n    File \"C:\\Users\\haris\\anaconda3\\envs\\tensorflow-gpu\\lib\\site-packages\\keras\\utils\\traceback_utils.py\", line 96, in error_handler\n      return fn(*args, **kwargs)\n    File \"C:\\Users\\haris\\anaconda3\\envs\\tensorflow-gpu\\lib\\site-packages\\keras\\engine\\functional.py\", line 510, in call\n      return self._run_internal_graph(inputs, training=training, mask=mask)\n    File \"C:\\Users\\haris\\anaconda3\\envs\\tensorflow-gpu\\lib\\site-packages\\keras\\engine\\functional.py\", line 667, in _run_internal_graph\n      outputs = node.layer(*args, **kwargs)\n    File \"C:\\Users\\haris\\anaconda3\\envs\\tensorflow-gpu\\lib\\site-packages\\keras\\utils\\traceback_utils.py\", line 65, in error_handler\n      return fn(*args, **kwargs)\n    File \"C:\\Users\\haris\\anaconda3\\envs\\tensorflow-gpu\\lib\\site-packages\\keras\\engine\\base_layer.py\", line 1097, in __call__\n      outputs = call_fn(inputs, *args, **kwargs)\n    File \"C:\\Users\\haris\\anaconda3\\envs\\tensorflow-gpu\\lib\\site-packages\\keras\\utils\\traceback_utils.py\", line 96, in error_handler\n      return fn(*args, **kwargs)\n    File \"C:\\Users\\haris\\anaconda3\\envs\\tensorflow-gpu\\lib\\site-packages\\keras\\layers\\convolutional\\separable_conv2d.py\", line 188, in call\n      outputs = tf.compat.v1.nn.separable_conv2d(\nNode: 'model/block2_sepconv1/separable_conv2d'\nOOM when allocating tensor with shape[32,109,109,128] and type float on /job:localhost/replica:0/task:0/device:GPU:0 by allocator GPU_0_bfc\n\t [[{{node model/block2_sepconv1/separable_conv2d}}]]\nHint: If you want to see a list of allocated tensors when OOM happens, add report_tensor_allocations_upon_oom to RunOptions for current allocation info. This isn't available when running in Eager mode.\n [Op:__inference_test_function_10248]",
     "output_type": "error",
     "traceback": [
      "\u001b[1;31m---------------------------------------------------------------------------\u001b[0m",
      "\u001b[1;31mResourceExhaustedError\u001b[0m                    Traceback (most recent call last)",
      "Cell \u001b[1;32mIn[5], line 29\u001b[0m\n\u001b[0;32m     26\u001b[0m history \u001b[38;5;241m=\u001b[39m model\u001b[38;5;241m.\u001b[39mfit(X_train, y_train, epochs\u001b[38;5;241m=\u001b[39m\u001b[38;5;241m10\u001b[39m, validation_data\u001b[38;5;241m=\u001b[39m(X_val, y_val))\n\u001b[0;32m     28\u001b[0m \u001b[38;5;66;03m# Evaluate the model on the test set\u001b[39;00m\n\u001b[1;32m---> 29\u001b[0m test_loss, test_acc \u001b[38;5;241m=\u001b[39m \u001b[43mmodel\u001b[49m\u001b[38;5;241;43m.\u001b[39;49m\u001b[43mevaluate\u001b[49m\u001b[43m(\u001b[49m\u001b[43mX_test\u001b[49m\u001b[43m,\u001b[49m\u001b[43m \u001b[49m\u001b[43my_test\u001b[49m\u001b[43m,\u001b[49m\u001b[43m \u001b[49m\u001b[43mverbose\u001b[49m\u001b[38;5;241;43m=\u001b[39;49m\u001b[38;5;241;43m2\u001b[39;49m\u001b[43m)\u001b[49m\n\u001b[0;32m     30\u001b[0m \u001b[38;5;28mprint\u001b[39m(\u001b[38;5;124m'\u001b[39m\u001b[38;5;130;01m\\n\u001b[39;00m\u001b[38;5;124mTest accuracy:\u001b[39m\u001b[38;5;124m'\u001b[39m, test_acc)\n",
      "File \u001b[1;32m~\\anaconda3\\envs\\tensorflow-gpu\\lib\\site-packages\\keras\\utils\\traceback_utils.py:70\u001b[0m, in \u001b[0;36mfilter_traceback.<locals>.error_handler\u001b[1;34m(*args, **kwargs)\u001b[0m\n\u001b[0;32m     67\u001b[0m     filtered_tb \u001b[38;5;241m=\u001b[39m _process_traceback_frames(e\u001b[38;5;241m.\u001b[39m__traceback__)\n\u001b[0;32m     68\u001b[0m     \u001b[38;5;66;03m# To get the full stack trace, call:\u001b[39;00m\n\u001b[0;32m     69\u001b[0m     \u001b[38;5;66;03m# `tf.debugging.disable_traceback_filtering()`\u001b[39;00m\n\u001b[1;32m---> 70\u001b[0m     \u001b[38;5;28;01mraise\u001b[39;00m e\u001b[38;5;241m.\u001b[39mwith_traceback(filtered_tb) \u001b[38;5;28;01mfrom\u001b[39;00m \u001b[38;5;28;01mNone\u001b[39;00m\n\u001b[0;32m     71\u001b[0m \u001b[38;5;28;01mfinally\u001b[39;00m:\n\u001b[0;32m     72\u001b[0m     \u001b[38;5;28;01mdel\u001b[39;00m filtered_tb\n",
      "File \u001b[1;32m~\\anaconda3\\envs\\tensorflow-gpu\\lib\\site-packages\\tensorflow\\python\\eager\\execute.py:54\u001b[0m, in \u001b[0;36mquick_execute\u001b[1;34m(op_name, num_outputs, inputs, attrs, ctx, name)\u001b[0m\n\u001b[0;32m     52\u001b[0m \u001b[38;5;28;01mtry\u001b[39;00m:\n\u001b[0;32m     53\u001b[0m   ctx\u001b[38;5;241m.\u001b[39mensure_initialized()\n\u001b[1;32m---> 54\u001b[0m   tensors \u001b[38;5;241m=\u001b[39m pywrap_tfe\u001b[38;5;241m.\u001b[39mTFE_Py_Execute(ctx\u001b[38;5;241m.\u001b[39m_handle, device_name, op_name,\n\u001b[0;32m     55\u001b[0m                                       inputs, attrs, num_outputs)\n\u001b[0;32m     56\u001b[0m \u001b[38;5;28;01mexcept\u001b[39;00m core\u001b[38;5;241m.\u001b[39m_NotOkStatusException \u001b[38;5;28;01mas\u001b[39;00m e:\n\u001b[0;32m     57\u001b[0m   \u001b[38;5;28;01mif\u001b[39;00m name \u001b[38;5;129;01mis\u001b[39;00m \u001b[38;5;129;01mnot\u001b[39;00m \u001b[38;5;28;01mNone\u001b[39;00m:\n",
      "\u001b[1;31mResourceExhaustedError\u001b[0m: Graph execution error:\n\nDetected at node 'model/block2_sepconv1/separable_conv2d' defined at (most recent call last):\n    File \"C:\\Users\\haris\\anaconda3\\envs\\tensorflow-gpu\\lib\\runpy.py\", line 196, in _run_module_as_main\n      return _run_code(code, main_globals, None,\n    File \"C:\\Users\\haris\\anaconda3\\envs\\tensorflow-gpu\\lib\\runpy.py\", line 86, in _run_code\n      exec(code, run_globals)\n    File \"C:\\Users\\haris\\anaconda3\\envs\\tensorflow-gpu\\lib\\site-packages\\ipykernel_launcher.py\", line 17, in <module>\n      app.launch_new_instance()\n    File \"C:\\Users\\haris\\anaconda3\\envs\\tensorflow-gpu\\lib\\site-packages\\traitlets\\config\\application.py\", line 1043, in launch_instance\n      app.start()\n    File \"C:\\Users\\haris\\anaconda3\\envs\\tensorflow-gpu\\lib\\site-packages\\ipykernel\\kernelapp.py\", line 712, in start\n      self.io_loop.start()\n    File \"C:\\Users\\haris\\anaconda3\\envs\\tensorflow-gpu\\lib\\site-packages\\tornado\\platform\\asyncio.py\", line 215, in start\n      self.asyncio_loop.run_forever()\n    File \"C:\\Users\\haris\\anaconda3\\envs\\tensorflow-gpu\\lib\\asyncio\\base_events.py\", line 603, in run_forever\n      self._run_once()\n    File \"C:\\Users\\haris\\anaconda3\\envs\\tensorflow-gpu\\lib\\asyncio\\base_events.py\", line 1909, in _run_once\n      handle._run()\n    File \"C:\\Users\\haris\\anaconda3\\envs\\tensorflow-gpu\\lib\\asyncio\\events.py\", line 80, in _run\n      self._context.run(self._callback, *self._args)\n    File \"C:\\Users\\haris\\anaconda3\\envs\\tensorflow-gpu\\lib\\site-packages\\ipykernel\\kernelbase.py\", line 510, in dispatch_queue\n      await self.process_one()\n    File \"C:\\Users\\haris\\anaconda3\\envs\\tensorflow-gpu\\lib\\site-packages\\ipykernel\\kernelbase.py\", line 499, in process_one\n      await dispatch(*args)\n    File \"C:\\Users\\haris\\anaconda3\\envs\\tensorflow-gpu\\lib\\site-packages\\ipykernel\\kernelbase.py\", line 406, in dispatch_shell\n      await result\n    File \"C:\\Users\\haris\\anaconda3\\envs\\tensorflow-gpu\\lib\\site-packages\\ipykernel\\kernelbase.py\", line 730, in execute_request\n      reply_content = await reply_content\n    File \"C:\\Users\\haris\\anaconda3\\envs\\tensorflow-gpu\\lib\\site-packages\\ipykernel\\ipkernel.py\", line 383, in do_execute\n      res = shell.run_cell(\n    File \"C:\\Users\\haris\\anaconda3\\envs\\tensorflow-gpu\\lib\\site-packages\\ipykernel\\zmqshell.py\", line 528, in run_cell\n      return super().run_cell(*args, **kwargs)\n    File \"C:\\Users\\haris\\anaconda3\\envs\\tensorflow-gpu\\lib\\site-packages\\IPython\\core\\interactiveshell.py\", line 3009, in run_cell\n      result = self._run_cell(\n    File \"C:\\Users\\haris\\anaconda3\\envs\\tensorflow-gpu\\lib\\site-packages\\IPython\\core\\interactiveshell.py\", line 3064, in _run_cell\n      result = runner(coro)\n    File \"C:\\Users\\haris\\anaconda3\\envs\\tensorflow-gpu\\lib\\site-packages\\IPython\\core\\async_helpers.py\", line 129, in _pseudo_sync_runner\n      coro.send(None)\n    File \"C:\\Users\\haris\\anaconda3\\envs\\tensorflow-gpu\\lib\\site-packages\\IPython\\core\\interactiveshell.py\", line 3269, in run_cell_async\n      has_raised = await self.run_ast_nodes(code_ast.body, cell_name,\n    File \"C:\\Users\\haris\\anaconda3\\envs\\tensorflow-gpu\\lib\\site-packages\\IPython\\core\\interactiveshell.py\", line 3448, in run_ast_nodes\n      if await self.run_code(code, result, async_=asy):\n    File \"C:\\Users\\haris\\anaconda3\\envs\\tensorflow-gpu\\lib\\site-packages\\IPython\\core\\interactiveshell.py\", line 3508, in run_code\n      exec(code_obj, self.user_global_ns, self.user_ns)\n    File \"C:\\Users\\haris\\AppData\\Local\\Temp\\ipykernel_16188\\2356912300.py\", line 26, in <module>\n      history = model.fit(X_train, y_train, epochs=10, validation_data=(X_val, y_val))\n    File \"C:\\Users\\haris\\anaconda3\\envs\\tensorflow-gpu\\lib\\site-packages\\keras\\utils\\traceback_utils.py\", line 65, in error_handler\n      return fn(*args, **kwargs)\n    File \"C:\\Users\\haris\\anaconda3\\envs\\tensorflow-gpu\\lib\\site-packages\\keras\\engine\\training.py\", line 1606, in fit\n      val_logs = self.evaluate(\n    File \"C:\\Users\\haris\\anaconda3\\envs\\tensorflow-gpu\\lib\\site-packages\\keras\\utils\\traceback_utils.py\", line 65, in error_handler\n      return fn(*args, **kwargs)\n    File \"C:\\Users\\haris\\anaconda3\\envs\\tensorflow-gpu\\lib\\site-packages\\keras\\engine\\training.py\", line 1947, in evaluate\n      tmp_logs = self.test_function(iterator)\n    File \"C:\\Users\\haris\\anaconda3\\envs\\tensorflow-gpu\\lib\\site-packages\\keras\\engine\\training.py\", line 1727, in test_function\n      return step_function(self, iterator)\n    File \"C:\\Users\\haris\\anaconda3\\envs\\tensorflow-gpu\\lib\\site-packages\\keras\\engine\\training.py\", line 1713, in step_function\n      outputs = model.distribute_strategy.run(run_step, args=(data,))\n    File \"C:\\Users\\haris\\anaconda3\\envs\\tensorflow-gpu\\lib\\site-packages\\keras\\engine\\training.py\", line 1701, in run_step\n      outputs = model.test_step(data)\n    File \"C:\\Users\\haris\\anaconda3\\envs\\tensorflow-gpu\\lib\\site-packages\\keras\\engine\\training.py\", line 1665, in test_step\n      y_pred = self(x, training=False)\n    File \"C:\\Users\\haris\\anaconda3\\envs\\tensorflow-gpu\\lib\\site-packages\\keras\\utils\\traceback_utils.py\", line 65, in error_handler\n      return fn(*args, **kwargs)\n    File \"C:\\Users\\haris\\anaconda3\\envs\\tensorflow-gpu\\lib\\site-packages\\keras\\engine\\training.py\", line 557, in __call__\n      return super().__call__(*args, **kwargs)\n    File \"C:\\Users\\haris\\anaconda3\\envs\\tensorflow-gpu\\lib\\site-packages\\keras\\utils\\traceback_utils.py\", line 65, in error_handler\n      return fn(*args, **kwargs)\n    File \"C:\\Users\\haris\\anaconda3\\envs\\tensorflow-gpu\\lib\\site-packages\\keras\\engine\\base_layer.py\", line 1097, in __call__\n      outputs = call_fn(inputs, *args, **kwargs)\n    File \"C:\\Users\\haris\\anaconda3\\envs\\tensorflow-gpu\\lib\\site-packages\\keras\\utils\\traceback_utils.py\", line 96, in error_handler\n      return fn(*args, **kwargs)\n    File \"C:\\Users\\haris\\anaconda3\\envs\\tensorflow-gpu\\lib\\site-packages\\keras\\engine\\functional.py\", line 510, in call\n      return self._run_internal_graph(inputs, training=training, mask=mask)\n    File \"C:\\Users\\haris\\anaconda3\\envs\\tensorflow-gpu\\lib\\site-packages\\keras\\engine\\functional.py\", line 667, in _run_internal_graph\n      outputs = node.layer(*args, **kwargs)\n    File \"C:\\Users\\haris\\anaconda3\\envs\\tensorflow-gpu\\lib\\site-packages\\keras\\utils\\traceback_utils.py\", line 65, in error_handler\n      return fn(*args, **kwargs)\n    File \"C:\\Users\\haris\\anaconda3\\envs\\tensorflow-gpu\\lib\\site-packages\\keras\\engine\\base_layer.py\", line 1097, in __call__\n      outputs = call_fn(inputs, *args, **kwargs)\n    File \"C:\\Users\\haris\\anaconda3\\envs\\tensorflow-gpu\\lib\\site-packages\\keras\\utils\\traceback_utils.py\", line 96, in error_handler\n      return fn(*args, **kwargs)\n    File \"C:\\Users\\haris\\anaconda3\\envs\\tensorflow-gpu\\lib\\site-packages\\keras\\layers\\convolutional\\separable_conv2d.py\", line 188, in call\n      outputs = tf.compat.v1.nn.separable_conv2d(\nNode: 'model/block2_sepconv1/separable_conv2d'\nOOM when allocating tensor with shape[32,109,109,128] and type float on /job:localhost/replica:0/task:0/device:GPU:0 by allocator GPU_0_bfc\n\t [[{{node model/block2_sepconv1/separable_conv2d}}]]\nHint: If you want to see a list of allocated tensors when OOM happens, add report_tensor_allocations_upon_oom to RunOptions for current allocation info. This isn't available when running in Eager mode.\n [Op:__inference_test_function_10248]"
     ]
    }
   ],
   "source": [
    "from tensorflow.keras.applications import Xception\n",
    "from tensorflow.keras.layers import GlobalAveragePooling2D, Dense\n",
    "from tensorflow.keras.models import Model\n",
    "\n",
    "# Load the Xception model pretrained on ImageNet\n",
    "base_model = Xception(weights='imagenet', include_top=False, input_shape=(224, 224, 3))\n",
    "\n",
    "# Freeze the layers in the base model\n",
    "for layer in base_model.layers:\n",
    "    layer.trainable = False\n",
    "\n",
    "# Add your custom classification head\n",
    "x = GlobalAveragePooling2D()(base_model.output)\n",
    "x = Dense(256, activation='relu')(x)\n",
    "x = Dense(120, activation='softmax')(x)  # 120 classes for dog breeds\n",
    "\n",
    "# Create the new model\n",
    "model = Model(inputs=base_model.input, outputs=x)\n",
    "\n",
    "# Compile the model\n",
    "model.compile(optimizer='adam',\n",
    "              loss='sparse_categorical_crossentropy',\n",
    "              metrics=['accuracy'])\n",
    "\n",
    "# Train the model\n",
    "history = model.fit(X_train, y_train, epochs=10, validation_data=(X_val, y_val))\n",
    "\n",
    "# Evaluate the model on the test set\n",
    "test_loss, test_acc = model.evaluate(X_test, y_test, verbose=2)\n",
    "print('\\nTest accuracy:', test_acc)"
   ]
  },
  {
   "cell_type": "code",
   "execution_count": null,
   "id": "b7bf4ac5-7bd7-4dfd-9627-8806191323a5",
   "metadata": {},
   "outputs": [],
   "source": []
  }
 ],
 "metadata": {
  "kernelspec": {
   "display_name": "Python 3.10 (tensorflow-gpu)",
   "language": "python",
   "name": "tensorflow-gpu"
  },
  "language_info": {
   "codemirror_mode": {
    "name": "ipython",
    "version": 3
   },
   "file_extension": ".py",
   "mimetype": "text/x-python",
   "name": "python",
   "nbconvert_exporter": "python",
   "pygments_lexer": "ipython3",
   "version": "3.10.12"
  }
 },
 "nbformat": 4,
 "nbformat_minor": 5
}
